2024-02-07 15:15:09 -0800    2468 execution.flow     INFO     Start executing nodes in thread pool mode.
2024-02-07 15:15:09 -0800    2468 execution.flow     INFO     Start to run 1 nodes with concurrency level 16.
2024-02-07 15:15:09 -0800    2468 execution.flow     INFO     Executing node ag_test. node run id: d8062490-4000-46ee-950f-dbb9eea7dd00_ag_test_0
2024-02-07 15:15:21 -0800    2468 execution          ERROR    Node ag_test in line 0 failed. Exception: Execution failure in 'ag_test': (NotFoundError) Error code: 404 - {'error': {'code': '404', 'message': 'Resource not found'}}.
Traceback (most recent call last):
  File "C:\Users\jacwang\AppData\Local\anaconda3\envs\autogen\Lib\site-packages\promptflow\_core\flow_execution_context.py", line 194, in _invoke_tool_with_timer
    return f(**kwargs)
           ^^^^^^^^^^^
  File "C:\Users\jacwang\AppData\Local\anaconda3\envs\autogen\Lib\site-packages\promptflow\_core\tracer.py", line 220, in wrapped
    output = func(*args, **kwargs)
             ^^^^^^^^^^^^^^^^^^^^^
  File "C:\repo\AzureOpenAIExamples\Examples\promptflow\finance_assistant_pf\ag_test.py", line 90, in my_python_tool
    assistant = client.beta.assistants.retrieve(assistant_id)
                ^^^^^^^^^^^^^^^^^^^^^^^^^^^^^^^^^^^^^^^^^^^^^
  File "C:\Users\jacwang\AppData\Local\anaconda3\envs\autogen\Lib\site-packages\openai\resources\beta\assistants\assistants.py", line 140, in retrieve
    return self._get(
           ^^^^^^^^^^
  File "C:\Users\jacwang\AppData\Local\anaconda3\envs\autogen\Lib\site-packages\openai\_base_client.py", line 1034, in get
    return cast(ResponseT, self.request(cast_to, opts, stream=stream, stream_cls=stream_cls))
                           ^^^^^^^^^^^^^^^^^^^^^^^^^^^^^^^^^^^^^^^^^^^^^^^^^^^^^^^^^^^^^^^^^
  File "C:\Users\jacwang\AppData\Local\anaconda3\envs\autogen\Lib\site-packages\openai\_base_client.py", line 852, in request
    return self._request(
           ^^^^^^^^^^^^^^
  File "C:\Users\jacwang\AppData\Local\anaconda3\envs\autogen\Lib\site-packages\openai\_base_client.py", line 933, in _request
    raise self._make_status_error_from_response(err.response) from None
openai.NotFoundError: Error code: 404 - {'error': {'code': '404', 'message': 'Resource not found'}}

The above exception was the direct cause of the following exception:

Traceback (most recent call last):
  File "C:\Users\jacwang\AppData\Local\anaconda3\envs\autogen\Lib\site-packages\promptflow\_core\flow_execution_context.py", line 90, in invoke_tool
    result = self._invoke_tool_with_timer(node, f, kwargs)
             ^^^^^^^^^^^^^^^^^^^^^^^^^^^^^^^^^^^^^^^^^^^^^
  File "C:\Users\jacwang\AppData\Local\anaconda3\envs\autogen\Lib\site-packages\promptflow\_core\flow_execution_context.py", line 205, in _invoke_tool_with_timer
    raise ToolExecutionError(node_name=node_name, module=module) from e
promptflow._core._errors.ToolExecutionError: Execution failure in 'ag_test': (NotFoundError) Error code: 404 - {'error': {'code': '404', 'message': 'Resource not found'}}
2024-02-07 15:15:21 -0800    2468 execution          ERROR    Execution of one node has failed. Cancelling all running nodes: ag_test.
